<sdf version="1.6">
  <world name="buoyant_tethys">
    <scene>
      <ambient>0.0 1.0 1.0</ambient>
      <background>0.0 0.7 0.8</background>
    </scene>

    <physics name="1ms" type="ode">
      <max_step_size>0.001</max_step_size>
      <real_time_factor>1.0</real_time_factor>
    </physics>

    <!-- Add plugins for the world -->
    <plugin filename="gz-sim-physics-system" name="gz::sim::systems::Physics"></plugin>
    <plugin filename="gz-sim-user-commands-system" name="gz::sim::systems::UserCommands"></plugin>
    <plugin filename="gz-sim-scene-broadcaster-system" name="gz::sim::systems::SceneBroadcaster"></plugin>
    <plugin filename="gz-sim-contact-system" name="gz::sim::systems::Contact"></plugin>
    <plugin filename="gz-sim-buoyancy-system" name="gz::sim::systems::Buoyancy">
      <uniform_fluid_density>1000</uniform_fluid_density>
    </plugin>

    <light type="directional" name="sun">
      <cast_shadows>true</cast_shadows>
      <pose>0 0 10 0 0 0</pose>
      <diffuse>1 1 1 1</diffuse>
      <specular>0.5 0.5 0.5 1</specular>
      <attenuation>
        <range>1000</range>
        <constant>0.9</constant>
        <linear>0.01</linear>
        <quadratic>0.001</quadratic>
      </attenuation>
      <direction>-0.5 0.1 -0.9</direction>
    </light>

    <!-- Buoyant box model -->
    <model name="buoyant_box">
      <pose>0 0 0 0 0 0</pose>
      <link name="body">
        <inertial>
          <mass>1000</mass>
          <inertia>
            <ixx>133.3333</ixx>
            <iyy>133.3333</iyy>
            <izz>133.3333</izz>
          </inertia>
        </inertial>
        <visual name="body_visual">
          <geometry>
            <box>
              <size>1 1 1</size>
            </box>
          </geometry>
        </visual>
        <collision name="body_collision">
          <geometry>
            <box>
              <size>1 1 1</size>
            </box>
          </geometry>
        </collision>
      </link>

      <!-- Left thruster -->
      <link name="left_thruster">
        <pose>-0.7 -0.2 -0.1 0 1.57 0</pose>
        <inertial>
          <mass>0</mass>
          <inertia>
            <ixx>0.1</ixx>
            <iyy>0.1</iyy>
            <izz>0.1</izz>
          </inertia>
        </inertial>
        <visual name="left_thruster_visual">
          <geometry>
            <cylinder>
              <radius>0.05</radius>
              <length>0.1</length>
            </cylinder>
          </geometry>
          <material>
            <ambient>0.2 0.2 0.2 1</ambient>
            <diffuse>0.5 0.5 0.5 1</diffuse>
          </material>
        </visual>
      </link>

      <!-- Right thruster -->
      <link name="right_thruster">
        <pose>-0.7 0.2 -0.1 0 1.57 0</pose>
        <inertial>
          <mass>0</mass>
          <inertia>
            <ixx>0.1</ixx>
            <iyy>0.1</iyy>
            <izz>0.1</izz>
          </inertia>
        </inertial>
        <visual name="right_thruster_visual">
          <geometry>
            <cylinder>
              <radius>0.05</radius>
              <length>0.1</length>
            </cylinder>
          </geometry>
          <material>
            <ambient>0.2 0.2 0.2 1</ambient>
            <diffuse>0.5 0.5 0.5 1</diffuse>
          </material>
        </visual>
      </link>

      <!-- Thruster joints -->
      <joint name="left_thruster_joint" type="revolute">
        <parent>body</parent>
        <child>left_thruster</child>
        <axis>
          <xyz>1 0 0</xyz>
        </axis>
      </joint>

      <joint name="right_thruster_joint" type="revolute">
        <parent>body</parent>
        <child>right_thruster</child>
        <axis>
          <xyz>1 0 0</xyz>
        </axis>
      </joint>

      <!-- Buoyancy engine plugin -->
      <plugin filename="gz-sim-buoyancy-engine-system" name="gz::sim::systems::BuoyancyEngine">
        <link_name>body</link_name>
        <namespace>buoyant_box</namespace>
        <min_volume>0.0</min_volume>
        <neutral_volume>0.002</neutral_volume>
        <default_volume>0.002</default_volume>
        <max_volume>0.003</max_volume>
        <max_inflation_rate>0.0003</max_inflation_rate>
      </plugin>

    </model>

    <!-- Buoyant box with surface -->
    <model name="buoyant_box_surface">
      <pose>0 5 -0.8 0 0 0</pose>
      <link name="body">
        <inertial>
          <mass>1000</mass>
          <inertia>
            <ixx>133.3333</ixx>
            <iyy>133.3333</iyy>
            <izz>133.3333</izz>
          </inertia>
        </inertial>
        <visual name="body_visual">
          <geometry>
            <box>
              <size>1 1 1</size>
            </box>
          </geometry>
        </visual>
        <collision name="body_collision">
          <geometry>
            <box>
              <size>1 1 1</size>
            </box>
          </geometry>
        </collision>
      </link>

      <plugin filename="gz-sim-buoyancy-engine-system" name="gz::sim::systems::BuoyancyEngine">
        <link_name>body</link_name>
        <namespace>buoyant_box</namespace>
        <min_volume>0.0</min_volume>
        <neutral_volume>0.002</neutral_volume>
        <default_volume>0.002</default_volume>
        <max_volume>0.003</max_volume>
        <max_inflation_rate>0.0003</max_inflation_rate>
        <surface>0</surface>
      </plugin>
    </model>

  </world>
</sdf>
